<?xml version="1.0" encoding="UTF-8"?>
<testng-results skipped="0" failed="1" ignored="0" total="2" passed="1">
  <reporter-output>
  </reporter-output>
  <suite name="Default suite" duration-ms="65" started-at="2018-10-27T04:40:24Z" finished-at="2018-10-27T04:40:24Z">
    <groups>
    </groups>
    <test name="Default test" duration-ms="65" started-at="2018-10-27T04:40:24Z" finished-at="2018-10-27T04:40:24Z">
      <class name="org.test.Test2">
        <test-method status="FAIL" signature="test1()[pri:0, instance:org.test.Test2@1c3a4799]" name="test1" duration-ms="18" started-at="2018-10-27T04:40:24Z" finished-at="2018-10-27T04:40:24Z">
          <exception class="java.lang.AssertionError">
            <message>
              <![CDATA[The following asserts failed:
expected [true] but found [false],
expected [true] but found [false]]]>
            </message>
            <full-stacktrace>
              <![CDATA[java.lang.AssertionError: The following asserts failed:
expected [true] but found [false],
expected [true] but found [false]
at org.testng.asserts.SoftAssert.assertAll(SoftAssert.java:43)
at org.test.Test2.test1(Test2.java:16)
at sun.reflect.NativeMethodAccessorImpl.invoke0(Native Method)
at sun.reflect.NativeMethodAccessorImpl.invoke(Unknown Source)
at sun.reflect.DelegatingMethodAccessorImpl.invoke(Unknown Source)
at java.lang.reflect.Method.invoke(Unknown Source)
at org.testng.internal.MethodInvocationHelper.invokeMethod(MethodInvocationHelper.java:124)
at org.testng.internal.Invoker.invokeMethod(Invoker.java:583)
at org.testng.internal.Invoker.invokeTestMethod(Invoker.java:719)
at org.testng.internal.Invoker.invokeTestMethods(Invoker.java:989)
at org.testng.internal.TestMethodWorker.invokeTestMethods(TestMethodWorker.java:125)
at org.testng.internal.TestMethodWorker.run(TestMethodWorker.java:109)
at org.testng.TestRunner.privateRun(TestRunner.java:648)
at org.testng.TestRunner.run(TestRunner.java:505)
at org.testng.SuiteRunner.runTest(SuiteRunner.java:455)
at org.testng.SuiteRunner.runSequentially(SuiteRunner.java:450)
at org.testng.SuiteRunner.privateRun(SuiteRunner.java:415)
at org.testng.SuiteRunner.run(SuiteRunner.java:364)
at org.testng.SuiteRunnerWorker.runSuite(SuiteRunnerWorker.java:52)
at org.testng.SuiteRunnerWorker.run(SuiteRunnerWorker.java:84)
at org.testng.TestNG.runSuitesSequentially(TestNG.java:1208)
at org.testng.TestNG.runSuitesLocally(TestNG.java:1137)
at org.testng.TestNG.runSuites(TestNG.java:1049)
at org.testng.TestNG.run(TestNG.java:1017)
at org.testng.remote.AbstractRemoteTestNG.run(AbstractRemoteTestNG.java:114)
at org.testng.remote.RemoteTestNG.initAndRun(RemoteTestNG.java:251)
at org.testng.remote.RemoteTestNG.main(RemoteTestNG.java:77)
]]>
            </full-stacktrace>
          </exception> <!-- java.lang.AssertionError -->
          <reporter-output>
          </reporter-output>
        </test-method> <!-- test1 -->
        <test-method status="PASS" signature="test2()[pri:0, instance:org.test.Test2@1c3a4799]" name="test2" duration-ms="2" started-at="2018-10-27T04:40:24Z" finished-at="2018-10-27T04:40:24Z">
          <reporter-output>
          </reporter-output>
        </test-method> <!-- test2 -->
      </class> <!-- org.test.Test2 -->
    </test> <!-- Default test -->
  </suite> <!-- Default suite -->
</testng-results>
